Workbook

Sheet Áttekintő
A2: Kiberbiztonsági jogszabályi feladatok
A3: V.1.0. Törvény és végrehajtási rendelet. 2026.09.13.
A5: Első tételes kivonat, teljes forrásszöveggel. A feladat- és jogjegyzék még nem teljes körű; a feldolgozottságot a Mutató mutatja.
A8: Feladatok és kötelezettségek | B8: =COUNTA(Feladatok!A6:A215) -> 210
A9: Jogok és hatáskörök | B9: =COUNTA(Jogok!A6:A46) -> 41
A10: Jogszabályi fogalmak | B10: =COUNTA(Fogalmak!A6:A131) -> 126
A12: Mit szeretnél megtalálni?
A13: =HYPERLINK("#'Hatály'!A1","Hatály") -> Hatály | B13: Kikre és mire vonatkozik?
A14: =HYPERLINK("#'Feladatok'!A1","Feladatok") -> Feladatok | B14: Mi az érintett feladata?
A15: =HYPERLINK("#'Jogok'!A1","Jogok") -> Jogok | B15: Mire jogosult, milyen hatáskörrel rendelkezik?
A16: =HYPERLINK("#'Fogalmak'!A1","Fogalmak") -> Fogalmak | B16: Mit jelent a jogszabályban használt fogalom?
A17: =HYPERLINK("#'Mutató'!A1","Mutató") -> Mutató | B17: Hol tart a tételes feldolgozás?
A18: =HYPERLINK("#'Forrásszöveg'!A1","Forrásszöveg") -> Forrásszöveg | B18: Mi a pontos rendelkezés?
A19: =HYPERLINK("#'Kapcsolatok'!A1","Kapcsolatok") -> Kapcsolatok | B19: Hol hivatkozik a Vhr. a törvényre?
A20: =HYPERLINK("#'Források'!A1","Források") -> Források | B20: Melyik változatból készült, hogyan bővíthető?
A22: Használat: válassz modult, szűrj az érintettre vagy témára, majd kattints a jogalapra. A „Teljes §” az összefüggő rendelkezések elejére visz.
A25: A kifejtés a két jogszabály tartalmára korlátozódik. Saját workflow, belső felelőskiosztás és bizonyítékigény nem szerepel benne.

Sheet Hatály
A2: Hatály, feltételek és kivételek | F2: =HYPERLINK("#'Áttekintő'!A1","Áttekintő") -> Áttekintő
A3: A szöveg együtt olvasandó a kapcsolódó mellékletekkel. A táblázat nem hoz szervezetre vonatkozó hatálydöntést.
A5: Azonosító | B5: Terület | C5: Jogszabályhely | D5: Szó szerinti rendelkezés / szövegkezdet | E5: Forrás | F5: Mellékletek
A6: H-TV-S0010 | B6: Személyi és tárgyi hatály, minősítés | C6: Tv. 1. § (1) | D6: 1. § (1) E törvénynek a szervezetek kötelezettségeire és a kiberbiztonsági hatósági felügyeletre vonatkozó rendelkezéseit kell alkalmazni a) az 1. mellékletben felsorolt, a közigazgatási ágazathoz tartozó szervezetekre, b) a többségi állami befolyás alatt álló azon gazdálkodó szervezetekre, amelyek nem tartoznak az a) pont hatálya alá és amelyek vonatkozásában legalább az egyik feltétel teljesül az alábbiak közül: ba) összes foglalkoztatotti létszáma eléri vagy meghaladja az 50 főt, vagy bb) éves nettó árbevétele vagy éves költségvetési bevételi előirányzata meghaladja a 10 millió eurónak megfelelő forintösszeget, és – a számvitelről szóló 2000. évi C. törvény 8. § (2) bekezdése szerinti beszámoló készítésére köteles szervezet esetében – mérlegfőösszege meghaladja a 10 millió eurónak megfelelő forintösszeget, c) a 23. § (1) bekezdés a) pontja szerinti nemzeti kiberbiztonsági hatóság (a továbbiakban: nemzeti kiberbiztonsági hatóság), vagy a 23. § (2) bekezdése szerinti honvédelmi kiberbiztonsági hatóság (a továbbiakban: honvédelmi kibe … [a teljes bekezdés a Forrás hivatkozáson] | E6: =HYPERLINK("#'Forrásszöveg'!A"&(MATCH("TV-S0010",Forrásszöveg!$A$6:$A$2497,0)+5),"Teljes bekezdés") -> Teljes bekezdés | F6: =HYPERLINK("#'Forrásszöveg'!A"&(MATCH("TV-S1258",Forrásszöveg!$A$6:$A$2497,0)+5),"Mellékletek") -> Mellékletek
A7: H-TV-S0026 | B7: Személyi és tárgyi hatály, minősítés | C7: Tv. 1. § (1a) | D7: (1a) Az (1) bekezdésben euróban meghatározott összegek forintra történő átszámításakor a Magyar Nemzeti Bank által közzétett, a szervezet üzleti évének lezárásakor vagy – költségvetési szerv esetében – a költségvetési év zárásakor érvényes hivatalos devizaárfolyamot kell alkalmazni. Újonnan alapított szervezet esetén a tárgyévet megelőző év utolsó napján érvényes, a Magyar Nemzeti Bank által közzétett hivatalos devizaárfolyamot kell alkalmazni. | E7: =HYPERLINK("#'Forrásszöveg'!A"&(MATCH("TV-S0026",Forrásszöveg!$A$6:$A$2497,0)+5),"Teljes bekezdés") -> Teljes bekezdés | F7: =HYPERLINK("#'Forrásszöveg'!A"&(MATCH("TV-S1258",Forrásszöveg!$A$6:$A$2497,0)+5),"Mellékletek") -> Mellékletek
A8: H-TV-S0027 | B8: Személyi és tárgyi hatály, minősítés | C8: Tv. 1. § (2) | D8: (2) A kritikus szervezetek ellenálló képességéről szóló törvény (a továbbiakban: Kszetv.) alapján kijelölt kritikus szervezetek és kritikus infrastruktúrák (a továbbiakban együtt: kritikus szervezet), valamint a védelmi és biztonsági tevékenységek összehangolásáról szóló törvény (a továbbiakban: Vbö.) alapján kijelölt, az ország védelme és biztonsága szempontjából jelentős szervezetek és infrastruktúrák (a továbbiakban együtt: az ország védelme és biztonsága szempontjából jelentős szervezet) vonatkozásában a szervezetnek az (1) bekezdés szerinti minősülése az irányadó e törvény rendelkezéseinek az alkalmazása során, kivéve, ha a kritikus szervezet vagy az ország védelme és biztonsága szempontjából jelentős szervezet az (EU) 2022/2554 európai parlamenti és tanácsi rendelet hatálya alá tartozik. | E8: =HYPERLINK("#'Forrásszöveg'!A"&(MATCH("TV-S0027",Forrásszöveg!$A$6:$A$2497,0)+5),"Teljes bekezdés") -> Teljes bekezdés | F8: =HYPERLINK("#'Forrásszöveg'!A"&(MATCH("TV-S1258",Forrásszöveg!$A$6:$A$2497,0)+5),"Mellékletek") -> Mellékletek
A9: H-TV-S0028 | B9: Személyi és tárgyi hatály, minősítés | C9: Tv. 1. § (2a) | D9: (2a) E törvénynek – a 9. § és a 13–15. § kivételével – az 1. § (1) bekezdés a) pontja szerinti szervezetekre irányadó rendelkezéseit kell alkalmazni arra a kritikus szervezetre vagy az ország védelme és biztonsága szempontjából jelentős szervezetre, amely nem minősül az (1) bekezdés szerinti szervezetnek. | E9: =HYPERLINK("#'Forrásszöveg'!A"&(MATCH("TV-S0028",Forrásszöveg!$A$6:$A$2497,0)+5),"Teljes bekezdés") -> Teljes bekezdés | F9: =HYPERLINK("#'Forrásszöveg'!A"&(MATCH("TV-S1258",Forrásszöveg!$A$6:$A$2497,0)+5),"Mellékletek") -> Mellékletek
A10: H-TV-S0029 | B10: Személyi és tárgyi hatály, minősítés | C10: Tv. 1. § (3) | D10: (3) A szervezetek – az általuk nyújtott szolgáltatásnak az állam, a társadalom, a gazdaság működése szempontjából való kritikussága, valamint bizonyos esetekben a szervezet mérete alapján – alapvető vagy fontos szervezeteknek minősülnek. | E10: =HYPERLINK("#'Forrásszöveg'!A"&(MATCH("TV-S0029",Forrásszöveg!$A$6:$A$2497,0)+5),"Teljes bekezdés") -> Teljes bekezdés | F10: =HYPERLINK("#'Forrásszöveg'!A"&(MATCH("TV-S1258",Forrásszöveg!$A$6:$A$2497,0)+5),"Mellékletek") -> Mellékletek
A11: H-TV-S0030 | B11: Személyi és tárgyi hatály, minősítés | C11: Tv. 1. § (4) | D11: (4) Az (1) bekezdés szerinti szervezetek közül alapvető szervezetnek minősülnek az alábbi szervezetek: a) az 1. melléklet szerinti szervezetek, kivéve a 20 000 főt meg nem haladó lakosságszámú települések képviselő-testületének hivatalai, b) az (1) bekezdés b) pontja szerinti szervezetek, c) azon szervezetek, amelyeket a nemzeti kiberbiztonsági hatóság vagy a honvédelmi kiberbiztonsági hatóság alapvető szervezetként azonosított, d) a Kszetv. alapján kijelölt kritikus szervezetek, e) a Vbö. alapján kijelölt, az ország védelme és biztonsága szempontjából jelentős szervezetek, f) a 2. melléklet szerinti azon szervezetek, amelyek a kis- és középvállalkozásokról, fejlődésük támogatásáról szóló törvény szerint középvállalkozásnak minősülnek vagy meghaladják a középvállalkozásokra vonatkozóan előírt küszöbértékeket, valamint g) a minősített bizalmi szolgáltatók és a legfelső szintű doménnév-nyilvántartók, valamint a DNS-szolgáltatók, méretüktől függetlenül, h) a honvédelmi érdekhez kapcsolódó tevékenységet folytató gazdasági társaságok. | E11: =HYPERLINK("#'Forrásszöveg'!A"&(MATCH("TV-S0030",Forrásszöveg!$A$6:$A$2497,0)+5),"Teljes bekezdés") -> Teljes bekezdés | F11: =HYPERLINK("#'Forrásszöveg'!A"&(MATCH("TV-S1258",Forrásszöveg!$A$6:$A$2497,0)+5),"Mellékletek") -> Mellékletek
A12: H-TV-S0039 | B12: Személyi és tárgyi hatály, minősítés | C12: Tv. 1. § (5) | D12: (5) Az (1) bekezdés szerinti szervezetek közül fontos szervezetnek minősülnek és a szervezetekre vonatkozó rendelkezéseket az e törvényben foglalt eltérésekkel kell alkalmazni az alábbi szervezetekre: a) a 20 000 főt meg nem haladó lakosságszámú települések képviselő-testületének hivatalai, b) azon szervezetek, amelyeket a nemzeti kiberbiztonsági hatóság vagy a honvédelmi kiberbiztonsági hatóság fontos szervezetként azonosított, c) a 2. melléklet szerinti szervezet, amely nem minősül alapvető szervezetnek, valamint d) a 3. melléklet szerinti szervezet, amely a (4) bekezdés b)–e) pontja alapján nem minősül alapvető szervezetnek. | E12: =HYPERLINK("#'Forrásszöveg'!A"&(MATCH("TV-S0039",Forrásszöveg!$A$6:$A$2497,0)+5),"Teljes bekezdés") -> Teljes bekezdés | F12: =HYPERLINK("#'Forrásszöveg'!A"&(MATCH("TV-S1258",Forrásszöveg!$A$6:$A$2497,0)+5),"Mellékletek") -> Mellékletek
A13: H-TV-S0044 | B13: Személyi és tárgyi hatály, minősítés | C13: Tv. 1. § (6) | D13: (6) Az (1) bekezdés c) pontja szerinti azonosítási eljárás feltétele, hogy a szervezet 1. Magyarországon egyedüli szolgáltatója egy olyan szolgáltatásnak, amely elengedhetetlen a kritikus társadalmi vagy gazdasági tevékenységek fenntartásához; 2. által nyújtott szolgáltatás zavara jelentős hatással lehet a közrendre, a közbiztonságra vagy a közegészségre; 3. által nyújtott szolgáltatás zavara jelentős hatást gyakorolhat kritikus fontosságú társadalmi vagy gazdasági tevékenységekre; 4. által nyújtott szolgáltatás zavara jelentős rendszerszintű kockázatot idézhet elő, különösen azokban az ágazatokban, ahol az említett zavarnak határokon átnyúló hatása lehet; 5. nemzeti vagy regionális szinten különös fontossággal bír az adott ágazat vagy szolgáltatás típusa, vagy más, hazai kölcsönösen függő ágazatok szempontjából; 6. a nemzetbiztonsági védelem alá eső szervek és létesítmények köréről szóló kormányhatározat alapján nemzetbiztonsági védelem alatt áll; vagy nemzetbiztonsági okból a nemzeti kiberbiztonsági hatóság, honvédelmi vagy katonai … [a teljes bekezdés a Forrás hivatkozáson] | E13: =HYPERLINK("#'Forrásszöveg'!A"&(MATCH("TV-S0044",Forrásszöveg!$A$6:$A$2497,0)+5),"Teljes bekezdés") -> Teljes bekezdés | F13: =HYPERLINK("#'Forrásszöveg'!A"&(MATCH("TV-S1258",Forrásszöveg!$A$6:$A$2497,0)+5),"Mellékletek") -> Mellékletek
A14: H-TV-S0058 | B14: Személyi és tárgyi hatály, minősítés | C14: Tv. 1. § (7) | D14: (7) E törvény kiberbiztonsági tanúsításra vonatkozó rendelkezéseit az információs és kommunikációs technológiai (a továbbiakban: IKT) termékek, IKT-szolgáltatások vagy IKT-folyamatok tanúsításával kapcsolatos tevékenységre kell alkalmazni. | E14: =HYPERLINK("#'Forrásszöveg'!A"&(MATCH("TV-S0058",Forrásszöveg!$A$6:$A$2497,0)+5),"Teljes bekezdés") -> Teljes bekezdés | F14: =HYPERLINK("#'Forrásszöveg'!A"&(MATCH("TV-S1258",Forrásszöveg!$A$6:$A$2497,0)+5),"Mellékletek") -> Mellékletek
A15: H-TV-S0059 | B15: Személyi és tárgyi hatály, minősítés | C15: Tv. 1. § (8) | D15: (8) E törvény poszt-kvantumtitkosításra vonatkozó rendelkezéseit a Szabályozott Tevékenységek Felügyeleti Hatósága (a továbbiakban: SZTFH) elnökének rendeletében meghatározott, a következő szervezetekre (a továbbiakban: poszt-kvantumtitkosítás alkalmazására kötelezett szervezet) és hatósági felügyeletükre irányuló tevékenységre kell alkalmazni: a) a kormányzati célú hálózatokról szóló kormányrendelet szerinti igénybevételre kötelezett szervezet, valamint b) a következő törvények hatálya alá tartozó közműszolgáltató és a következő törvények felhatalmazása alapján kiadott jogszabályok hatálya alá tartozó, közszolgáltatást nyújtó szervezet: ba) a földgázellátásról szóló törvény, bb) a földgáz biztonsági készletezéséről szóló törvény, bc) a villamos energiáról szóló törvény, bd) a távhőszolgáltatásról szóló törvény, be) a víziközmű-szolgáltatásról szóló törvény, valamint bf) a hulladékról szóló törvény. | E15: =HYPERLINK("#'Forrásszöveg'!A"&(MATCH("TV-S0059",Forrásszöveg!$A$6:$A$2497,0)+5),"Teljes bekezdés") -> Teljes bekezdés | F15: =HYPERLINK("#'Forrásszöveg'!A"&(MATCH("TV-S1258",Forrásszöveg!$A$6:$A$2497,0)+5),"Mellékletek") -> Mellékletek
A16: H-TV-S0068 | B16: Személyi és tárgyi hatály, minősítés | C16: Tv. 1. § (9) | D16: (9) E törvény sérülékenységvizsgálatra vonatkozó rendelkezéseit kell alkalmazni: a) az (1) bekezdés a)–c) és f) pontja szerinti szervezetek elektronikus információs rendszereit, valamint b) a megállapodásban foglalt eltérésekkel a 61. § szerinti megállapodásban meghatározott elektronikus információs rendszereket érintő sérülékenységvizsgálatokra. | E16: =HYPERLINK("#'Forrásszöveg'!A"&(MATCH("TV-S0068",Forrásszöveg!$A$6:$A$2497,0)+5),"Teljes bekezdés") -> Teljes bekezdés | F16: =HYPERLINK("#'Forrásszöveg'!A"&(MATCH("TV-S1258",Forrásszöveg!$A$6:$A$2497,0)+5),"Mellékletek") -> Mellékletek
A17: H-TV-S0072 | B17: Személyi és tárgyi hatály, minősítés | C17: Tv. 1. § (10) | D17: (10) E törvény kiberbiztonsági incidenskezelésre vonatkozó rendelkezéseit kell alkalmazni: a) az (1) bekezdés szerinti szervezetek, valamint b) az e törvényben meghatározott eltérésekkel az (EU) 2022/2554 európai parlamenti és tanácsi rendelet hatálya alá tartozó szervezetek elektronikus információs rendszereit érintő kiberbiztonsági incidensek kezelésére. | E17: =HYPERLINK("#'Forrásszöveg'!A"&(MATCH("TV-S0072",Forrásszöveg!$A$6:$A$2497,0)+5),"Teljes bekezdés") -> Teljes bekezdés | F17: =HYPERLINK("#'Forrásszöveg'!A"&(MATCH("TV-S1258",Forrásszöveg!$A$6:$A$2497,0)+5),"Mellékletek") -> Mellékletek
A18: H-TV-S0076 | B18: Személyi és tárgyi hatály, minősítés | C18: Tv. 1. § (11) | D18: (11) A (10) bekezdésben meghatározott szervezeteken kívüli szervezetek, illetve személyek által önkéntesen bejelentett kiberbiztonsági incidensek esetén a nemzeti kiberbiztonsági incidenskezelő központ az e törvényben meghatározottak szerint jár el. | E18: =HYPERLINK("#'Forrásszöveg'!A"&(MATCH("TV-S0076",Forrásszöveg!$A$6:$A$2497,0)+5),"Teljes bekezdés") -> Teljes bekezdés | F18: =HYPERLINK("#'Forrásszöveg'!A"&(MATCH("TV-S1258",Forrásszöveg!$A$6:$A$2497,0)+5),"Mellékletek") -> Mellékletek
A19: H-TV-S0077 | B19: Területi alkalmazás | C19: Tv. 2. § (1) | D19: 2. § (1) E törvény rendelkezéseit kell alkalmazni a) a Magyarország területén letelepedett vagy letelepedett képviselővel rendelkező 1. § szerinti szervezetekre, b) a Magyarország területén szolgáltatást nyújtó elektronikus hírközlési szolgáltatókra, c) azokra a DNS-szolgáltatókra, legfelső szintű doménnév-nyilvántartókra, doménnév-nyilvántartási szolgáltatásokat nyújtó szervezetekre, felhőszolgáltatókra, adatközpont-szolgáltatókra, tartalomszolgáltató hálózati szolgáltatókra, kihelyezett (irányított) infokommunikációs szolgáltatást nyújtó szolgáltatókra, kihelyezett (irányított) infokommunikációs biztonsági szolgáltatást nyújtó szolgáltatókra, az online piacterek, online keresőprogramok és közösségimédia-szolgáltatási platformok szolgáltatóira, amelyek üzleti tevékenységének fő helye Magyarország területén található. | E19: =HYPERLINK("#'Forrásszöveg'!A"&(MATCH("TV-S0077",Forrásszöveg!$A$6:$A$2497,0)+5),"Teljes bekezdés") -> Teljes bekezdés | F19: =HYPERLINK("#'Forrásszöveg'!A"&(MATCH("TV-S1258",Forrásszöveg!$A$6:$A$2497,0)+5),"Mellékletek") -> Mellékletek
A20: H-TV-S0081 | B20: Területi alkalmazás | C20: Tv. 2. § (2) | D20: (2) Az (1) bekezdés c) pontja szerinti szervezet üzleti tevékenységének fő helye abban az esetben van Magyarországon, ha a) a kiberbiztonsági kockázatkezelési intézkedésekkel kapcsolatos döntéseket túlnyomórészt Magyarországon hozzák meg, b) a szervezet elektronikus információs rendszereivel kapcsolatos kiberbiztonsági műveleteket Magyarországon végzik, vagy c) a szervezetnek a legmagasabb munkavállalói létszámmal rendelkező telephelye Magyarországon van. | E20: =HYPERLINK("#'Forrásszöveg'!A"&(MATCH("TV-S0081",Forrásszöveg!$A$6:$A$2497,0)+5),"Teljes bekezdés") -> Teljes bekezdés | F20: =HYPERLINK("#'Forrásszöveg'!A"&(MATCH("TV-S1258",Forrásszöveg!$A$6:$A$2497,0)+5),"Mellékletek") -> Mellékletek
A21: H-TV-S0085 | B21: Kivételek és eltérések | C21: Tv. 3. § (1) | D21: 3. § (1) E törvény hatálya nem terjed ki a) a minősített adatot kezelő elektronikus információs rendszerekre, b) a műveleti célú elektronikus információs rendszerekre, c) az atomenergia alkalmazása körében a fizikai védelemről és a kapcsolódó engedélyezési, jelentési és ellenőrzési rendszerről szóló kormányrendelet hatálya alá tartozó programozható rendszerekre, valamint d) a Kormány rendeletében kijelölt szerv által nyújtott kiberbiztonsági szolgáltatásokra. | E21: =HYPERLINK("#'Forrásszöveg'!A"&(MATCH("TV-S0085",Forrásszöveg!$A$6:$A$2497,0)+5),"Teljes bekezdés") -> Teljes bekezdés | F21: =HYPERLINK("#'Forrásszöveg'!A"&(MATCH("TV-S1258",Forrásszöveg!$A$6:$A$2497,0)+5),"Mellékletek") -> Mellékletek
A22: H-TV-S0090 | B22: Kivételek és eltérések | C22: Tv. 3. § (2) | D22: (2) A Kormány rendeletében határozza meg az (1) bekezdés d) pontja szerinti kiberbiztonsági szolgáltatások körét és az igénybevételére kötelezett, illetve jogosult szervezetek körét. | E22: =HYPERLINK("#'Forrásszöveg'!A"&(MATCH("TV-S0090",Forrásszöveg!$A$6:$A$2497,0)+5),"Teljes bekezdés") -> Teljes bekezdés | F22: =HYPERLINK("#'Forrásszöveg'!A"&(MATCH("TV-S1258",Forrásszöveg!$A$6:$A$2497,0)+5),"Mellékletek") -> Mellékletek
A23: H-TV-S0091 | B23: Kivételek és eltérések | C23: Tv. 3. § (3) | D23: (3) E törvény rendelkezéseit a honvédelmi célú elektronikus információs rendszerek vonatkozásában az e törvényben meghatározott eltérésekkel kell alkalmazni. | E23: =HYPERLINK("#'Forrásszöveg'!A"&(MATCH("TV-S0091",Forrásszöveg!$A$6:$A$2497,0)+5),"Teljes bekezdés") -> Teljes bekezdés | F23: =HYPERLINK("#'Forrásszöveg'!A"&(MATCH("TV-S1258",Forrásszöveg!$A$6:$A$2497,0)+5),"Mellékletek") -> Mellékletek
A24: H-TV-S0276 | B24: Különös feltétel / kivétel | C24: Tv. 6. § (10) | D24: (10) Az 1. § (1) bekezdés a) és c) pontja hatálya alá tartozó fontos szervezet, valamint a 2. és 3. melléklet szerinti szervezetnek nem minősülő, 1. § (1) bekezdés b) pontja hatálya alá tartozó szervezet rendelkezésében lévő elektronikus információs rendszerek vonatkozásában a) nem szükséges a (2) bekezdésben foglalt teljes körű kockázatmenedzsment keretrendszert működtetni, b) nem kell teljesíteni a (3) bekezdés 4–5. és 9. pontjában foglaltakat, valamint c) legalább az „alap” biztonsági osztályra irányadó követelményeket kell teljesíteni. | E24: =HYPERLINK("#'Forrásszöveg'!A"&(MATCH("TV-S0276",Forrásszöveg!$A$6:$A$2497,0)+5),"Teljes bekezdés") -> Teljes bekezdés | F24: =HYPERLINK("#'Forrásszöveg'!A"&(MATCH("TV-S1258",Forrásszöveg!$A$6:$A$2497,0)+5),"Mellékletek") -> Mellékletek
A25: H-TV-S0298 | B25: Különös feltétel / kivétel | C25: Tv. 8. § (6) | D25: (6) A (4) és (5) bekezdés alkalmazása szempontjából az e törvény hatálya alá kerülés időpontja a) új szervezet esetében a szervezet létesítésének, b) az 1. § (1) bekezdés b) vagy d) pontja szerinti esetben ba) az e törvény hatálya alá kerülésre okot adó feltétel bekövetkezését követő év első, vagy bb) ha a szervezet a ba) alpont szerinti napot megelőzően benyújtott nyilvántartásba vételi kérelmében ezt kéri, a szervezet nyilvántartásba vételéről szóló döntés véglegessé válásának, c) a hatály alá kerülést eredményező jogállást megalapozó jogi aktus hatálybalépésének napja. | E25: =HYPERLINK("#'Forrásszöveg'!A"&(MATCH("TV-S0298",Forrásszöveg!$A$6:$A$2497,0)+5),"Teljes bekezdés") -> Teljes bekezdés | F25: =HYPERLINK("#'Forrásszöveg'!A"&(MATCH("TV-S1258",Forrásszöveg!$A$6:$A$2497,0)+5),"Mellékletek") -> Mellékletek
A26: H-TV-S0305 | B26: Különös feltétel / kivétel | C26: Tv. 8. § (6a) | D26: (6a) Ha az 1. § (1) bekezdés b) vagy d) pontja szerinti szervezet esetében az e törvény hatálya alá kerülésre okot adó 1. § (1) bekezdés b) pont ba) vagy bb) alpontja, illetve 1. § (1) bekezdés d) pont da) vagy db) alpontja szerinti feltétel megszűnik, az e törvény hatálya alól történő kikerülés időpontja a feltétel megszűnését követő második év vége. | E26: =HYPERLINK("#'Forrásszöveg'!A"&(MATCH("TV-S0305",Forrásszöveg!$A$6:$A$2497,0)+5),"Teljes bekezdés") -> Teljes bekezdés | F26: =HYPERLINK("#'Forrásszöveg'!A"&(MATCH("TV-S1258",Forrásszöveg!$A$6:$A$2497,0)+5),"Mellékletek") -> Mellékletek
A27: H-TV-S0324 | B27: Különös feltétel / kivétel | C27: Tv. 11. § (3) | D27: (3) Az elektronikus információs rendszer biztonságáért felelős személy feladatait csak olyan személy végezheti, aki a) cselekvőképes, büntetlen előéletű és b) az 1. § (1) bekezdés a)–c) és f) pontja szerinti szervezet, a Kszetv. alapján kritikus szervezetként kijelölt szervezet, valamint a Vbö. alapján az ország védelme és biztonsága szempontjából jelentős szervezetként kijelölt szervezet esetében rendelkezik a feladatellátáshoz szükséges, az informatikáért felelős miniszter rendeletében előírt végzettséggel, valamint rendelkezik ba) a 75. § (1) bekezdése szerinti nemzeti koordinációs központ által – az informatikáért felelős miniszter rendeletében foglaltak szerint – közzétett szakképzettséggel, akkreditált nemzetközi képzettséggel (a továbbiakban együtt: szakképzettség), vagy bb) az informatikáért felelős miniszter rendeletében meghatározott szakterületen szerzett szakmai tapasztalattal. | E27: =HYPERLINK("#'Forrásszöveg'!A"&(MATCH("TV-S0324",Forrásszöveg!$A$6:$A$2497,0)+5),"Teljes bekezdés") -> Teljes bekezdés | F27: =HYPERLINK("#'Forrásszöveg'!A"&(MATCH("TV-S1258",Forrásszöveg!$A$6:$A$2497,0)+5),"Mellékletek") -> Mellékletek
A28: H-TV-S0329 | B28: Különös feltétel / kivétel | C28: Tv. 11. § (4) | D28: (4) Elektronikus információs rendszer biztonságáért felelős személyként – az (5) bekezdésben foglalt kivétellel – nem jelölhető ki vagy bízható meg a szervezet gazdasági vezetői feladatait ellátó személy vagy az a személy, aki a szervezeten belül informatikai üzemeltetéssel, informatikai fejlesztéssel kapcsolatos munkakört lát el, illetve ilyen személy közvetlen alárendeltségébe tartozik. | E28: =HYPERLINK("#'Forrásszöveg'!A"&(MATCH("TV-S0329",Forrásszöveg!$A$6:$A$2497,0)+5),"Teljes bekezdés") -> Teljes bekezdés | F28: =HYPERLINK("#'Forrásszöveg'!A"&(MATCH("TV-S1258",Forrásszöveg!$A$6:$A$2497,0)+5),"Mellékletek") -> Mellékletek
A29: H-TV-S0330 | B29: Különös feltétel / kivétel | C29: Tv. 11. § (5) | D29: (5) A (4) bekezdést nem kell alkalmazni a következő szervezetek vonatkozásában: a) az 1. § (1) bekezdés a)–c) pontja szerinti fontos szervezetek, b) az 1. § (1) bekezdés d) és e) pontja szerinti szervezetek. | E29: =HYPERLINK("#'Forrásszöveg'!A"&(MATCH("TV-S0330",Forrásszöveg!$A$6:$A$2497,0)+5),"Teljes bekezdés") -> Teljes bekezdés | F29: =HYPERLINK("#'Forrásszöveg'!A"&(MATCH("TV-S1258",Forrásszöveg!$A$6:$A$2497,0)+5),"Mellékletek") -> Mellékletek
A30: H-TV-S0357 | B30: Különös feltétel / kivétel | C30: Tv. 13. § (1) | D30: 13. § (1) Új elektronikus információs rendszerek fejlesztése, vagy már meglévő elektronikus információs rendszerek továbbfejlesztése (a továbbiakban együtt: fejlesztés) vonatkozásában jelen alcím rendelkezéseit kell alkalmazni az alábbi, alapvető szervezetnek minősülő szervezetek esetében a) az 1. § (1) bekezdés a) és c) pontja szerinti szervezet, valamint b) az 1. § (1) bekezdés b) pontja szerinti és egyben a 2. és 3. melléklet szerinti szervezetnek minősülő szervezet. | E30: =HYPERLINK("#'Forrásszöveg'!A"&(MATCH("TV-S0357",Forrásszöveg!$A$6:$A$2497,0)+5),"Teljes bekezdés") -> Teljes bekezdés | F30: =HYPERLINK("#'Forrásszöveg'!A"&(MATCH("TV-S1258",Forrásszöveg!$A$6:$A$2497,0)+5),"Mellékletek") -> Mellékletek
A31: H-TV-S0372 | B31: Különös feltétel / kivétel | C31: Tv. 13/A. § | D31: 13/A. § A jelen alcím rendelkezéseit az 1. § (1) bekezdés f) pontja szerinti szervezet honvédelmi célú elektronikus információs rendszerei fejlesztésére is alkalmazni kell. | E31: =HYPERLINK("#'Forrásszöveg'!A"&(MATCH("TV-S0372",Forrásszöveg!$A$6:$A$2497,0)+5),"Teljes bekezdés") -> Teljes bekezdés | F31: =HYPERLINK("#'Forrásszöveg'!A"&(MATCH("TV-S1258",Forrásszöveg!$A$6:$A$2497,0)+5),"Mellékletek") -> Mellékletek
A32: H-TV-S0373 | B32: Különös feltétel / kivétel | C32: Tv. 14. § (1) | D32: 14. § (1) Ha az elektronikus információs rendszer fejlesztése a) a 2. vagy 3. melléklet szerinti szervezetnek nem minősülő, az 1. § (1) bekezdés b) pontja szerinti alapvető szervezet vagy b) az 1. § (1) bekezdés a) és c) pontja szerinti fontos szervezet által történik, a 13. §-ban foglaltak helyett e § rendelkezései az irányadóak. | E32: =HYPERLINK("#'Forrásszöveg'!A"&(MATCH("TV-S0373",Forrásszöveg!$A$6:$A$2497,0)+5),"Teljes bekezdés") -> Teljes bekezdés | F32: =HYPERLINK("#'Forrásszöveg'!A"&(MATCH("TV-S1258",Forrásszöveg!$A$6:$A$2497,0)+5),"Mellékletek") -> Mellékletek
A33: H-TV-S0387 | B33: Különös feltétel / kivétel | C33: Tv. 16. § (1) | D33: 16. § (1) Az 1. § (1) bekezdés b) pontja szerinti azon szervezet, amely egyúttal a 2. és 3. melléklet szerinti szervezet is, valamint az 1. § (1) bekezdés d) pontja és – a kis- és középvállalkozásokról, fejlődésük támogatásáról szóló törvény szerinti mikrovállalkozás kivételével – az 1. § (1) bekezdés e) pontja szerinti szervezet az e törvény szerinti kiberbiztonsági követelményeknek való megfelelés bizonyítására köteles kétévente, illetve a 23. § (1) bekezdése szerint illetékes kiberbiztonsági hatóság általi elrendelés esetén kiberbiztonsági auditot végeztetni. | E33: =HYPERLINK("#'Forrásszöveg'!A"&(MATCH("TV-S0387",Forrásszöveg!$A$6:$A$2497,0)+5),"Teljes bekezdés") -> Teljes bekezdés | F33: =HYPERLINK("#'Forrásszöveg'!A"&(MATCH("TV-S1258",Forrásszöveg!$A$6:$A$2497,0)+5),"Mellékletek") -> Mellékletek
A34: H-TV-S0391 | B34: Különös feltétel / kivétel | C34: Tv. 16. § (3) | D34: (3) A honvédelmi célú elektronikus információs rendszerek tekintetében kiberbiztonsági audit nem végezhető. | E34: =HYPERLINK("#'Forrásszöveg'!A"&(MATCH("TV-S0391",Forrásszöveg!$A$6:$A$2497,0)+5),"Teljes bekezdés") -> Teljes bekezdés | F34: =HYPERLINK("#'Forrásszöveg'!A"&(MATCH("TV-S1258",Forrásszöveg!$A$6:$A$2497,0)+5),"Mellékletek") -> Mellékletek
A35: H-TV-S0992 | B35: Különös feltétel / kivétel | C35: Tv. 71. § (1) | D35: 71. § (1) Az (EU) 2022/2554 európai parlamenti és tanácsi rendelet hatálya alá tartozó szervezetek kiberbiztonsági incidenseinek kezelése során a 63–64. §, a 67. §, a 68. § (1) bekezdése, a 69. §, valamint a 70. § (10), (13) és (14) bekezdése szerinti rendelkezések alkalmazandóak. | E35: =HYPERLINK("#'Forrásszöveg'!A"&(MATCH("TV-S0992",Forrásszöveg!$A$6:$A$2497,0)+5),"Teljes bekezdés") -> Teljes bekezdés | F35: =HYPERLINK("#'Forrásszöveg'!A"&(MATCH("TV-S1258",Forrásszöveg!$A$6:$A$2497,0)+5),"Mellékletek") -> Mellékletek
A36: H-TV-S1203 | B36: Különös feltétel / kivétel | C36: Tv. 83. § (1) | D36: 83. § (1) Az állami és önkormányzati szervek elektronikus információbiztonságáról szóló 2013. évi L. törvény (a továbbiakban: Ibtv.) szerinti nyilvántartásban 2024. december 31. napján szereplő – 8. § (4) bekezdés szerinti adatok körébe tartozó – adatokat nem kell ismételten bejelenteni, azokat a nemzeti kiberbiztonsági hatóság a 28. § (1) bekezdése szerinti nyilvántartás részeként kezeli. | E36: =HYPERLINK("#'Forrásszöveg'!A"&(MATCH("TV-S1203",Forrásszöveg!$A$6:$A$2497,0)+5),"Teljes bekezdés") -> Teljes bekezdés | F36: =HYPERLINK("#'Forrásszöveg'!A"&(MATCH("TV-S1258",Forrásszöveg!$A$6:$A$2497,0)+5),"Mellékletek") -> Mellékletek
A37: H-TV-S1207 | B37: Különös feltétel / kivétel | C37: Tv. 83. § (3) | D37: (3) Ha az 1. § (1) bekezdés a) és b) pontja szerinti szervezet az elektronikus információs rendszer biztonságáért felelős személy adatait az Ibtv. alapján már bejelentette a nemzeti kiberbiztonsági hatóság részére, úgy annak ismételt bejelentésére nem köteles. | E37: =HYPERLINK("#'Forrásszöveg'!A"&(MATCH("TV-S1207",Forrásszöveg!$A$6:$A$2497,0)+5),"Teljes bekezdés") -> Teljes bekezdés | F37: =HYPERLINK("#'Forrásszöveg'!A"&(MATCH("TV-S1258",Forrásszöveg!$A$6:$A$2497,0)+5),"Mellékletek") -> Mellékletek
A38: H-TV-S1226 | B38: Különös feltétel / kivétel | C38: Tv. 89. § (3) | D38: (3) Az a gazdálkodó szervezet, amely a kiberbiztonsági tanúsításról és a kiberbiztonsági felügyeletről szóló 2023. évi XXIII. törvény 26. § (1) bekezdése szerint vezetett nyilvántartásban érintett szervezetként szerepel, és 2024. december 31. napjáig a kiberbiztonsági tanúsításról és a kiberbiztonsági felügyeletről szóló 2023. évi XXIII. törvény 20. § (1) bekezdése szerint az elektronikus információs rendszereinek, valamint az azon tárolt, továbbított vagy feldolgozott adatoknak a biztonsági osztályba sorolását elvégezte, nem köteles a 10. § (1) bekezdése alapján ismételten elvégezni a biztonsági osztályba sorolást. | E38: =HYPERLINK("#'Forrásszöveg'!A"&(MATCH("TV-S1226",Forrásszöveg!$A$6:$A$2497,0)+5),"Teljes bekezdés") -> Teljes bekezdés | F38: =HYPERLINK("#'Forrásszöveg'!A"&(MATCH("TV-S1258",Forrásszöveg!$A$6:$A$2497,0)+5),"Mellékletek") -> Mellékletek
A39: H-VHR-S0032 | B39: Vhr. alkalmazási köre | C39: Vhr. 1. § (1) | D39: 1. § (1) E rendeletnek a szervezetek kötelezettségeire és a kiberbiztonság hatósági felügyeletére vonatkozó rendelkezéseit – a (2) bekezdésben foglalt kivétellel – a Magyarország kiberbiztonságáról szóló 2024. évi LXIX. törvény (a továbbiakban: Kiberbiztonsági tv.) 1. § (1) bekezdés a)–c) és f) pontja, valamint 1. § (2a) bekezdése szerinti szervezetekre kell alkalmazni. | E39: =HYPERLINK("#'Forrásszöveg'!A"&(MATCH("VHR-S0032",Forrásszöveg!$A$6:$A$2497,0)+5),"Teljes bekezdés") -> Teljes bekezdés | F39: =HYPERLINK("#'Forrásszöveg'!A"&(MATCH("VHR-S1069",Forrásszöveg!$A$6:$A$2497,0)+5),"Mellékletek") -> Mellékletek
A40: H-VHR-S0033 | B40: Vhr. alkalmazási köre | C40: Vhr. 1. § (2) | D40: (2) E rendeletnek az elektronikus információs rendszer biztonságáért felelős személyre vonatkozó rendelkezéseit az alábbi szervezetekre kell alkalmazni: a) a Kiberbiztonsági tv. 1. § (1) bekezdés a)–c) és f) pontja, valamint 1. § (2a) bekezdése szerinti szervezetekre, b) a Kiberbiztonsági tv. 1. § (1) bekezdés d) és e) pontja szerinti azon szervezetekre, amelyek a kritikus szervezetek ellenálló képességéről szóló 2024. évi LXXXIV. törvény (a továbbiakban: Kszetv.) alapján kritikus szervezetként vannak kijelölve, vagy a Kszetv. alapján kritikus infrastruktúraként kijelölt infrastruktúrát üzemeltetnek (a továbbiakban együtt: kritikus szervezet), valamint c) a Kiberbiztonsági tv. 1. § (1) bekezdés d) és e) pontja szerinti azon szervezetekre, amelyek a védelmi és biztonsági tevékenységek összehangolásáról szóló 2021. évi XCIII. törvény (a továbbiakban: Vbö.) alapján az ország védelme és biztonsága szempontjából jelentős szervezetként kerültek kijelölésre vagy a Vbö. alapján az ország védelme és biztonsága szempontjából jelentős infrastruk … [a teljes bekezdés a Forrás hivatkozáson] | E40: =HYPERLINK("#'Forrásszöveg'!A"&(MATCH("VHR-S0033",Forrásszöveg!$A$6:$A$2497,0)+5),"Teljes bekezdés") -> Teljes bekezdés | F40: =HYPERLINK("#'Forrásszöveg'!A"&(MATCH("VHR-S1069",Forrásszöveg!$A$6:$A$2497,0)+5),"Mellékletek") -> Mellékletek
A41: H-VHR-S0037 | B41: Vhr. alkalmazási köre | C41: Vhr. 1. § (3) | D41: (3) E rendeletnek a kiberbiztonsági gyakorlatokra, valamint a kiberbiztonsági bírságokra vonatkozó rendelkezéseit a Kiberbiztonsági tv. 1. § (1) bekezdése szerinti szervezetekre kell alkalmazni. | E41: =HYPERLINK("#'Forrásszöveg'!A"&(MATCH("VHR-S0037",Forrásszöveg!$A$6:$A$2497,0)+5),"Teljes bekezdés") -> Teljes bekezdés | F41: =HYPERLINK("#'Forrásszöveg'!A"&(MATCH("VHR-S1069",Forrásszöveg!$A$6:$A$2497,0)+5),"Mellékletek") -> Mellékletek
A42: H-VHR-S0038 | B42: Vhr. alkalmazási köre | C42: Vhr. 1. § (4) | D42: (4) E rendelet kiberbiztonsági tanúsításra vonatkozó rendelkezéseit az információs és kommunikációs technológiai (a továbbiakban: IKT) termékek, IKT-szolgáltatások vagy IKT-folyamatok (a továbbiakban együtt: IKT-termék) tanúsításával kapcsolatos tevékenység vonatkozásában kell alkalmazni. | E42: =HYPERLINK("#'Forrásszöveg'!A"&(MATCH("VHR-S0038",Forrásszöveg!$A$6:$A$2497,0)+5),"Teljes bekezdés") -> Teljes bekezdés | F42: =HYPERLINK("#'Forrásszöveg'!A"&(MATCH("VHR-S1069",Forrásszöveg!$A$6:$A$2497,0)+5),"Mellékletek") -> Mellékletek
...

Sheet Feladatok
A2: Feladatok és kötelezettségek | H2: =HYPERLINK("#'Áttekintő'!A1","Áttekintő") -> Áttekintő
A3: Első tételes kivonat, nem teljes körű. Szűrés: érintett vagy téma; a jogalapra kattintva a pontos szöveg nyílik meg.
A5: Azonosító | B5: Érintett | C5: Feladat röviden | D5: Feltétel / kivétel | E5: Időzítés | F5: Jogalap | G5: Téma | H5: Teljes §
A6: F-TV-0241 | B6: Szervezet vezetője | C6: Kockázatmenedzsment keretrendszer létrehozása és működtetése | D6: Figyelembe veendő a Tv. 6. § (10) szerinti eltérés. | E6: A tétel jogalapjában nincs külön időpont kiemelve. | F6: =HYPERLINK("#'Forrásszöveg'!A"&(MATCH("TV-S0241",Forrásszöveg!$A$6:$A$2497,0)+5),"Tv. 6. § (2)") -> Tv. 6. § (2) | G6: Az alapvető és fontos szervezetek általános kötelezettségei | H6: =HYPERLINK("#'Forrásszöveg'!A"&(MATCH("TV-S0240",Forrásszöveg!$A$6:$A$2497,0)+5),"6. § eleje") -> 6. § eleje
A7: F-TV-0243 | B7: Szervezet vezetője | C7: Használt rendszerek és központi szolgáltatások felmérése, nyilvántartása | D7: A Tv. 6. § (3) 1. pont a)–d) alpontja szerinti bontásban. | E7: A tétel jogalapjában nincs külön időpont kiemelve. | F7: =HYPERLINK("#'Forrásszöveg'!A"&(MATCH("TV-S0243",Forrásszöveg!$A$6:$A$2497,0)+5),"Tv. 6. § (3) 1.") -> Tv. 6. § (3) 1. | G7: Az alapvető és fontos szervezetek általános kötelezettségei | H7: =HYPERLINK("#'Forrásszöveg'!A"&(MATCH("TV-S0240",Forrásszöveg!$A$6:$A$2497,0)+5),"6. § eleje") -> 6. § eleje
A8: F-TV-0248 | B8: Szervezet vezetője | C8: Szerepkörök, felelősök és hatáskörök meghatározása; felelős személy kinevezése vagy megbízása | D8: A Tv. 6. § (3) szerinti feltételekkel; a 6. § (10) eltérései külön vizsgálandók. | E8: A tétel jogalapjában nincs külön időpont kiemelve. | F8: =HYPERLINK("#'Forrásszöveg'!A"&(MATCH("TV-S0248",Forrásszöveg!$A$6:$A$2497,0)+5),"Tv. 6. § (3) 2.") -> Tv. 6. § (3) 2. | G8: Az alapvető és fontos szervezetek általános kötelezettségei | H8: =HYPERLINK("#'Forrásszöveg'!A"&(MATCH("TV-S0240",Forrásszöveg!$A$6:$A$2497,0)+5),"6. § eleje") -> 6. § eleje
A9: F-TV-0249 | B9: Szervezet vezetője | C9: Adatok felméréséről és osztályozásáról gondoskodás | D9: A Tv. 1. melléklete szerinti szervezet; a 6. § (3) 1. a) szerinti EIR adatai. | E9: A tétel jogalapjában nincs külön időpont kiemelve. | F9: =HYPERLINK("#'Forrásszöveg'!A"&(MATCH("TV-S0249",Forrásszöveg!$A$6:$A$2497,0)+5),"Tv. 6. § (3) 3.") -> Tv. 6. § (3) 3. | G9: Az alapvető és fontos szervezetek általános kötelezettségei | H9: =HYPERLINK("#'Forrásszöveg'!A"&(MATCH("TV-S0240",Forrásszöveg!$A$6:$A$2497,0)+5),"6. § eleje") -> 6. § eleje
A10: F-TV-0250 | B10: Szervezet vezetője | C10: Hatáselemzés és kockázatmenedzsment végzése | D10: A Tv. 6. § (3) szerinti feltételekkel; a 6. § (10) eltérései külön vizsgálandók. | E10: A tétel jogalapjában nincs külön időpont kiemelve. | F10: =HYPERLINK("#'Forrásszöveg'!A"&(MATCH("TV-S0250",Forrásszöveg!$A$6:$A$2497,0)+5),"Tv. 6. § (3) 4.") -> Tv. 6. § (3) 4. | G10: Az alapvető és fontos szervezetek általános kötelezettségei | H10: =HYPERLINK("#'Forrásszöveg'!A"&(MATCH("TV-S0240",Forrásszöveg!$A$6:$A$2497,0)+5),"6. § eleje") -> 6. § eleje
A11: F-TV-0251 | B11: Szervezet vezetője | C11: Elektronikus információs rendszerek biztonsági osztályba sorolása | D11: A Tv. 6. § (3) szerinti feltételekkel; a 6. § (10) eltérései külön vizsgálandók. | E11: A tétel jogalapjában nincs külön időpont kiemelve. | F11: =HYPERLINK("#'Forrásszöveg'!A"&(MATCH("TV-S0251",Forrásszöveg!$A$6:$A$2497,0)+5),"Tv. 6. § (3) 5.") -> Tv. 6. § (3) 5. | G11: Az alapvető és fontos szervezetek általános kötelezettségei | H11: =HYPERLINK("#'Forrásszöveg'!A"&(MATCH("TV-S0240",Forrásszöveg!$A$6:$A$2497,0)+5),"6. § eleje") -> 6. § eleje
A12: F-TV-0252 | B12: Szervezet vezetője | C12: Kockázatarányos védelmi intézkedések meghatározása | D12: A Tv. 6. § (3) szerinti feltételekkel; a 6. § (10) eltérései külön vizsgálandók. | E12: A tétel jogalapjában nincs külön időpont kiemelve. | F12: =HYPERLINK("#'Forrásszöveg'!A"&(MATCH("TV-S0252",Forrásszöveg!$A$6:$A$2497,0)+5),"Tv. 6. § (3) 6.") -> Tv. 6. § (3) 6. | G12: Az alapvető és fontos szervezetek általános kötelezettségei | H12: =HYPERLINK("#'Forrásszöveg'!A"&(MATCH("TV-S0240",Forrásszöveg!$A$6:$A$2497,0)+5),"6. § eleje") -> 6. § eleje
A13: F-TV-0253 | B13: Szervezet vezetője | C13: Információbiztonsági szabályzat kiadása és felülvizsgálata | D13: A Tv. 6. § (3) szerinti feltételekkel; a 6. § (10) eltérései külön vizsgálandók. | E13: Legalább kétévente, vagy jogszabályban meghatározott esetben. | F13: =HYPERLINK("#'Forrásszöveg'!A"&(MATCH("TV-S0253",Forrásszöveg!$A$6:$A$2497,0)+5),"Tv. 6. § (3) 7.") -> Tv. 6. § (3) 7. | G13: Az alapvető és fontos szervezetek általános kötelezettségei | H13: =HYPERLINK("#'Forrásszöveg'!A"&(MATCH("TV-S0240",Forrásszöveg!$A$6:$A$2497,0)+5),"6. § eleje") -> 6. § eleje
A14: F-TV-0254 | B14: Szervezet vezetője | C14: Védelmi intézkedések teljesülésének biztosítása | D14: A Tv. 6. § (3) szerinti feltételekkel; a 6. § (10) eltérései külön vizsgálandók. | E14: A tétel jogalapjában nincs külön időpont kiemelve. | F14: =HYPERLINK("#'Forrásszöveg'!A"&(MATCH("TV-S0254",Forrásszöveg!$A$6:$A$2497,0)+5),"Tv. 6. § (3) 8.") -> Tv. 6. § (3) 8. | G14: Az alapvető és fontos szervezetek általános kötelezettségei | H14: =HYPERLINK("#'Forrásszöveg'!A"&(MATCH("TV-S0240",Forrásszöveg!$A$6:$A$2497,0)+5),"6. § eleje") -> 6. § eleje
A15: F-TV-0255 | B15: Szervezet vezetője | C15: Védelmi intézkedések értékelése az első besoroláskor | D15: A Tv. 6. § (3) szerinti feltételekkel; a 6. § (10) eltérései külön vizsgálandók. | E15: A tétel jogalapjában nincs külön időpont kiemelve. | F15: =HYPERLINK("#'Forrásszöveg'!A"&(MATCH("TV-S0255",Forrásszöveg!$A$6:$A$2497,0)+5),"Tv. 6. § (3) 9.") -> Tv. 6. § (3) 9. | G15: Az alapvető és fontos szervezetek általános kötelezettségei | H15: =HYPERLINK("#'Forrásszöveg'!A"&(MATCH("TV-S0240",Forrásszöveg!$A$6:$A$2497,0)+5),"6. § eleje") -> 6. § eleje
A16: F-TV-0256 | B16: Szervezet vezetője | C16: Védelmi intézkedések rendszeres értékelése | D16: A Tv. 6. § (3) szerinti feltételekkel; a 6. § (10) eltérései külön vizsgálandók. | E16: A tétel jogalapjában nincs külön időpont kiemelve. | F16: =HYPERLINK("#'Forrásszöveg'!A"&(MATCH("TV-S0256",Forrásszöveg!$A$6:$A$2497,0)+5),"Tv. 6. § (3) 10.") -> Tv. 6. § (3) 10. | G16: Az alapvető és fontos szervezetek általános kötelezettségei | H16: =HYPERLINK("#'Forrásszöveg'!A"&(MATCH("TV-S0240",Forrásszöveg!$A$6:$A$2497,0)+5),"6. § eleje") -> 6. § eleje
A17: F-TV-0257 | B17: Szervezet vezetője | C17: Feltárt hiányosságok orvoslása | D17: A Tv. 6. § (3) szerinti feltételekkel; a 6. § (10) eltérései külön vizsgálandók. | E17: A tétel jogalapjában nincs külön időpont kiemelve. | F17: =HYPERLINK("#'Forrásszöveg'!A"&(MATCH("TV-S0257",Forrásszöveg!$A$6:$A$2497,0)+5),"Tv. 6. § (3) 11.") -> Tv. 6. § (3) 11. | G17: Az alapvető és fontos szervezetek általános kötelezettségei | H17: =HYPERLINK("#'Forrásszöveg'!A"&(MATCH("TV-S0240",Forrásszöveg!$A$6:$A$2497,0)+5),"6. § eleje") -> 6. § eleje
A18: F-TV-0258 | B18: Szervezet vezetője | C18: Döntés a használatbavételről vagy a használat folytatásáról | D18: A Tv. 6. § (3) szerinti feltételekkel; a 6. § (10) eltérései külön vizsgálandók. | E18: A tétel jogalapjában nincs külön időpont kiemelve. | F18: =HYPERLINK("#'Forrásszöveg'!A"&(MATCH("TV-S0258",Forrásszöveg!$A$6:$A$2497,0)+5),"Tv. 6. § (3) 12.") -> Tv. 6. § (3) 12. | G18: Az alapvető és fontos szervezetek általános kötelezettségei | H18: =HYPERLINK("#'Forrásszöveg'!A"&(MATCH("TV-S0240",Forrásszöveg!$A$6:$A$2497,0)+5),"6. § eleje") -> 6. § eleje
A19: F-TV-0259 | B19: Szervezet vezetője | C19: Hatósági kötelezések teljesítése | D19: A Tv. 6. § (3) szerinti feltételekkel; a 6. § (10) eltérései külön vizsgálandók. | E19: A tétel jogalapjában nincs külön időpont kiemelve. | F19: =HYPERLINK("#'Forrásszöveg'!A"&(MATCH("TV-S0259",Forrásszöveg!$A$6:$A$2497,0)+5),"Tv. 6. § (3) 13.") -> Tv. 6. § (3) 13. | G19: Az alapvető és fontos szervezetek általános kötelezettségei | H19: =HYPERLINK("#'Forrásszöveg'!A"&(MATCH("TV-S0240",Forrásszöveg!$A$6:$A$2497,0)+5),"6. § eleje") -> 6. § eleje
A20: F-TV-0260 | B20: Szervezet vezetője | C20: A 6. § (3) 10. pont szerinti értékelések végrehajtása | D20: Az IBSZ felülvizsgálatával, és ha kötelező, a besorolás felülvizsgálatával együtt. | E20: Legalább kétévente. | F20: =HYPERLINK("#'Forrásszöveg'!A"&(MATCH("TV-S0260",Forrásszöveg!$A$6:$A$2497,0)+5),"Tv. 6. § (4)") -> Tv. 6. § (4) | G20: Az alapvető és fontos szervezetek általános kötelezettségei | H20: =HYPERLINK("#'Forrásszöveg'!A"&(MATCH("TV-S0240",Forrásszöveg!$A$6:$A$2497,0)+5),"6. § eleje") -> 6. § eleje
A21: F-TV-0262 | B21: Szervezet vezetője | C21: Védelmi feladatok oktatása és kiberbiztonsági képzés, továbbképzés biztosítása | D21: A hivatkozott rendelkezés és az alkalmazandó hatályszabályok szerint. | E21: A tétel jogalapjában nincs külön időpont kiemelve. | F21: =HYPERLINK("#'Forrásszöveg'!A"&(MATCH("TV-S0262",Forrásszöveg!$A$6:$A$2497,0)+5),"Tv. 6. § (5) a)") -> Tv. 6. § (5) a) | G21: Az alapvető és fontos szervezetek általános kötelezettségei | H21: =HYPERLINK("#'Forrásszöveg'!A"&(MATCH("TV-S0240",Forrásszöveg!$A$6:$A$2497,0)+5),"6. § eleje") -> 6. § eleje
A22: F-TV-0263 | B22: Szervezet vezetője | C22: Kötelező gyakorlaton részvétel vagy önálló gyakorlat megtartásának biztosítása | D22: A hivatkozott rendelkezés és az alkalmazandó hatályszabályok szerint. | E22: A tétel jogalapjában nincs külön időpont kiemelve. | F22: =HYPERLINK("#'Forrásszöveg'!A"&(MATCH("TV-S0263",Forrásszöveg!$A$6:$A$2497,0)+5),"Tv. 6. § (5) b)") -> Tv. 6. § (5) b) | G22: Az alapvető és fontos szervezetek általános kötelezettségei | H22: =HYPERLINK("#'Forrásszöveg'!A"&(MATCH("TV-S0240",Forrásszöveg!$A$6:$A$2497,0)+5),"6. § eleje") -> 6. § eleje
A23: F-TV-0264 | B23: Szervezet vezetője | C23: Elektronikus információs rendszer eseményei nyomonkövethetőségének biztosítása | D23: A hivatkozott rendelkezés és az alkalmazandó hatályszabályok szerint. | E23: A tétel jogalapjában nincs külön időpont kiemelve. | F23: =HYPERLINK("#'Forrásszöveg'!A"&(MATCH("TV-S0264",Forrásszöveg!$A$6:$A$2497,0)+5),"Tv. 6. § (5) c)") -> Tv. 6. § (5) c) | G23: Az alapvető és fontos szervezetek általános kötelezettségei | H23: =HYPERLINK("#'Forrásszöveg'!A"&(MATCH("TV-S0240",Forrásszöveg!$A$6:$A$2497,0)+5),"6. § eleje") -> 6. § eleje
A24: F-TV-0265 | B24: Szervezet vezetője | C24: Közreműködőre vonatkozó kiberbiztonsági követelmények szerződéses előírása | D24: A hivatkozott rendelkezés és az alkalmazandó hatályszabályok szerint. | E24: A tétel jogalapjában nincs külön időpont kiemelve. | F24: =HYPERLINK("#'Forrásszöveg'!A"&(MATCH("TV-S0265",Forrásszöveg!$A$6:$A$2497,0)+5),"Tv. 6. § (5) d)") -> Tv. 6. § (5) d) | G24: Az alapvető és fontos szervezetek általános kötelezettségei | H24: =HYPERLINK("#'Forrásszöveg'!A"&(MATCH("TV-S0240",Forrásszöveg!$A$6:$A$2497,0)+5),"6. § eleje") -> 6. § eleje
A25: F-TV-0266 | B25: Szervezet vezetője | C25: Reagálás, incidensbejelentés, kezelés és helyreállítás biztosítása | D25: A hivatkozott rendelkezés és az alkalmazandó hatályszabályok szerint. | E25: A tétel jogalapjában nincs külön időpont kiemelve. | F25: =HYPERLINK("#'Forrásszöveg'!A"&(MATCH("TV-S0266",Forrásszöveg!$A$6:$A$2497,0)+5),"Tv. 6. § (5) e)") -> Tv. 6. § (5) e) | G25: Az alapvető és fontos szervezetek általános kötelezettségei | H25: =HYPERLINK("#'Forrásszöveg'!A"&(MATCH("TV-S0240",Forrásszöveg!$A$6:$A$2497,0)+5),"6. § eleje") -> 6. § eleje
A26: F-TV-0267 | B26: Szervezet vezetője | C26: Érintettek haladéktalan tájékoztatása incidensekről és fenyegetésekről | D26: A hivatkozott rendelkezés és az alkalmazandó hatályszabályok szerint. | E26: Haladéktalanul. | F26: =HYPERLINK("#'Forrásszöveg'!A"&(MATCH("TV-S0267",Forrásszöveg!$A$6:$A$2497,0)+5),"Tv. 6. § (5) f)") -> Tv. 6. § (5) f) | G26: Az alapvető és fontos szervezetek általános kötelezettségei | H26: =HYPERLINK("#'Forrásszöveg'!A"&(MATCH("TV-S0240",Forrásszöveg!$A$6:$A$2497,0)+5),"6. § eleje") -> 6. § eleje
A27: F-TV-0268 | B27: Szervezet vezetője | C27: Hatósági és incidenskezelő központi ajánlások figyelembevétele | D27: A hivatkozott rendelkezés és az alkalmazandó hatályszabályok szerint. | E27: A tétel jogalapjában nincs külön időpont kiemelve. | F27: =HYPERLINK("#'Forrásszöveg'!A"&(MATCH("TV-S0268",Forrásszöveg!$A$6:$A$2497,0)+5),"Tv. 6. § (5) g)") -> Tv. 6. § (5) g) | G27: Az alapvető és fontos szervezetek általános kötelezettségei | H27: =HYPERLINK("#'Forrásszöveg'!A"&(MATCH("TV-S0240",Forrásszöveg!$A$6:$A$2497,0)+5),"6. § eleje") -> 6. § eleje
A28: F-TV-0269 | B28: Szervezet vezetője | C28: Törekvés a feladatok lehető legrövidebb időn belüli végrehajtására | D28: A hivatkozott rendelkezés és az alkalmazandó hatályszabályok szerint. | E28: A tétel jogalapjában nincs külön időpont kiemelve. | F28: =HYPERLINK("#'Forrásszöveg'!A"&(MATCH("TV-S0269",Forrásszöveg!$A$6:$A$2497,0)+5),"Tv. 6. § (5) h)") -> Tv. 6. § (5) h) | G28: Az alapvető és fontos szervezetek általános kötelezettségei | H28: =HYPERLINK("#'Forrásszöveg'!A"&(MATCH("TV-S0240",Forrásszöveg!$A$6:$A$2497,0)+5),"6. § eleje") -> 6. § eleje
A29: F-TV-0270 | B29: Szervezet vezetője | C29: Kiberbiztonsági fejlesztési ráfordítás biztosítása | D29: A Tv. 1. § (1) a)–c) pontja szerinti szervezet. | E29: A tárgyév során; az informatikai fejlesztési költségek legalább 5%-ának megfelelő összeg. | F29: =HYPERLINK("#'Forrásszöveg'!A"&(MATCH("TV-S0270",Forrásszöveg!$A$6:$A$2497,0)+5),"Tv. 6. § (5) i)") -> Tv. 6. § (5) i) | G29: Az alapvető és fontos szervezetek általános kötelezettségei | H29: =HYPERLINK("#'Forrásszöveg'!A"&(MATCH("TV-S0240",Forrásszöveg!$A$6:$A$2497,0)+5),"6. § eleje") -> 6. § eleje
A30: F-TV-0271 | B30: Szervezet vezetője | C30: További szükséges védelmi intézkedések megtétele | D30: A hivatkozott rendelkezés és az alkalmazandó hatályszabályok szerint. | E30: A tétel jogalapjában nincs külön időpont kiemelve. | F30: =HYPERLINK("#'Forrásszöveg'!A"&(MATCH("TV-S0271",Forrásszöveg!$A$6:$A$2497,0)+5),"Tv. 6. § (5) j)") -> Tv. 6. § (5) j) | G30: Az alapvető és fontos szervezetek általános kötelezettségei | H30: =HYPERLINK("#'Forrásszöveg'!A"&(MATCH("TV-S0240",Forrásszöveg!$A$6:$A$2497,0)+5),"6. § eleje") -> 6. § eleje
A31: F-TV-0275 | B31: Szervezet | C31: Előírt tanúsított IKT-termék, szolgáltatás vagy folyamat használata | D31: A hivatkozott miniszteri vagy SZTFH-rendeletben meghatározott szervezetek és termékek. Külső részletszabály nincs kibontva. | E31: A tétel jogalapjában nincs külön időpont kiemelve. | F31: =HYPERLINK("#'Forrásszöveg'!A"&(MATCH("TV-S0275",Forrásszöveg!$A$6:$A$2497,0)+5),"Tv. 6. § (9)") -> Tv. 6. § (9) | G31: Az alapvető és fontos szervezetek általános kötelezettségei | H31: =HYPERLINK("#'Forrásszöveg'!A"&(MATCH("TV-S0240",Forrásszöveg!$A$6:$A$2497,0)+5),"6. § eleje") -> 6. § eleje
A32: F-TV-0279 | B32: Szervezet | C32: Legalább az alap biztonsági osztály követelményeinek teljesítése | D32: Kizárólag a Tv. 6. § (10) bevezető részében megjelölt szervezetek és rendszerek. | E32: A tétel jogalapjában nincs külön időpont kiemelve. | F32: =HYPERLINK("#'Forrásszöveg'!A"&(MATCH("TV-S0279",Forrásszöveg!$A$6:$A$2497,0)+5),"Tv. 6. § (10) c)") -> Tv. 6. § (10) c) | G32: Az alapvető és fontos szervezetek általános kötelezettségei | H32: =HYPERLINK("#'Forrásszöveg'!A"&(MATCH("TV-S0240",Forrásszöveg!$A$6:$A$2497,0)+5),"6. § eleje") -> 6. § eleje
A33: F-TV-0280 | B33: Szervezet | C33: Honvédelmi rendszerhez kapcsolódó bejelentések és kötelezettségek teljesítése | D33: Honvédelmi célú EIR; címzett a honvédelmi kiberbiztonsági hatóság. | E33: A tétel jogalapjában nincs külön időpont kiemelve. | F33: =HYPERLINK("#'Forrásszöveg'!A"&(MATCH("TV-S0280",Forrásszöveg!$A$6:$A$2497,0)+5),"Tv. 6. § (11)") -> Tv. 6. § (11) | G33: Az alapvető és fontos szervezetek általános kötelezettségei | H33: =HYPERLINK("#'Forrásszöveg'!A"&(MATCH("TV-S0240",Forrásszöveg!$A$6:$A$2497,0)+5),"6. § eleje") -> 6. § eleje
A34: F-TV-0282 | B34: Szervezet | C34: Kiberbiztonsági felügyeleti díj fizetése | D34: A Tv. 7. § (1) szerinti kör, költségvetési kivétel és vállalatcsoport-szabály mellett. | E34: Az SZTFH elnökének rendelete szerint. | F34: =HYPERLINK("#'Forrásszöveg'!A"&(MATCH("TV-S0282",Forrásszöveg!$A$6:$A$2497,0)+5),"Tv. 7. § (1)") -> Tv. 7. § (1) | G34: Az alapvető és fontos szervezetek általános kötelezettségei | H34: =HYPERLINK("#'Forrásszöveg'!A"&(MATCH("TV-S0282",Forrásszöveg!$A$6:$A$2497,0)+5),"7. § eleje") -> 7. § eleje
A35: F-TV-0285 | B35: Szervezet | C35: Magyarországon működő képviselő írásbeli kijelölése | D35: Nem Magyarországon bejegyzett, a törvény hatálya alá tartozó EIR-t működtető szervezet. | E35: A tétel jogalapjában nincs külön időpont kiemelve. | F35: =HYPERLINK("#'Forrásszöveg'!A"&(MATCH("TV-S0285",Forrásszöveg!$A$6:$A$2497,0)+5),"Tv. 8. § (1)") -> Tv. 8. § (1) | G35: Az alapvető és fontos szervezetek általános kötelezettségei | H35: =HYPERLINK("#'Forrásszöveg'!A"&(MATCH("TV-S0285",Forrásszöveg!$A$6:$A$2497,0)+5),"8. § eleje") -> 8. § eleje
A36: F-TV-0286 | B36: Szervezet vezetője | C36: Hatósággal való együttműködés biztosítása | D36: A hivatkozott rendelkezés és az alkalmazandó hatályszabályok szerint. | E36: A tétel jogalapjában nincs külön időpont kiemelve. | F36: =HYPERLINK("#'Forrásszöveg'!A"&(MATCH("TV-S0286",Forrásszöveg!$A$6:$A$2497,0)+5),"Tv. 8. § (2)") -> Tv. 8. § (2) | G36: Az alapvető és fontos szervezetek általános kötelezettségei | H36: =HYPERLINK("#'Forrásszöveg'!A"&(MATCH("TV-S0285",Forrásszöveg!$A$6:$A$2497,0)+5),"8. § eleje") -> 8. § eleje
A37: F-TV-0288 | B37: Szervezet vezetője | C37: Nyilvántartási adatok, iratok és változásaik megküldése | D37: A jogszabályban és a hatóság honlapján meghatározottak szerint. | E37: Változás esetén a változást követő 14 napon belül. | F37: =HYPERLINK("#'Forrásszöveg'!A"&(MATCH("TV-S0288",Forrásszöveg!$A$6:$A$2497,0)+5),"Tv. 8. § (3) a)") -> Tv. 8. § (3) a) | G37: Az alapvető és fontos szervezetek általános kötelezettségei | H37: =HYPERLINK("#'Forrásszöveg'!A"&(MATCH("TV-S0285",Forrásszöveg!$A$6:$A$2497,0)+5),"8. § eleje") -> 8. § eleje
A38: F-TV-0289 | B38: Szervezet vezetője | C38: Hatósági ellenőrzés feltételeinek biztosítása | D38: A hivatkozott rendelkezés és az alkalmazandó hatályszabályok szerint. | E38: A tétel jogalapjában nincs külön időpont kiemelve. | F38: =HYPERLINK("#'Forrásszöveg'!A"&(MATCH("TV-S0289",Forrásszöveg!$A$6:$A$2497,0)+5),"Tv. 8. § (3) b)") -> Tv. 8. § (3) b) | G38: Az alapvető és fontos szervezetek általános kötelezettségei | H38: =HYPERLINK("#'Forrásszöveg'!A"&(MATCH("TV-S0285",Forrásszöveg!$A$6:$A$2497,0)+5),"8. § eleje") -> 8. § eleje
A39: F-TV-0291 | B39: Szervezet | C39: Szervezeti adatok bejelentése | D39: Tv. 1. § (1) a)–c), f); a Tv. 8. § (4), (6) és az 51. alcím figyelembevételével. | E39: A hatály alá kerülést követő 30 napon belül; átmeneti eltérések: Tv. 83–89. §. | F39: =HYPERLINK("#'Forrásszöveg'!A"&(MATCH("TV-S0291",Forrásszöveg!$A$6:$A$2497,0)+5),"Tv. 8. § (4) a)") -> Tv. 8. § (4) a) | G39: Az alapvető és fontos szervezetek általános kötelezettségei | H39: =HYPERLINK("#'Forrásszöveg'!A"&(MATCH("TV-S0285",Forrásszöveg!$A$6:$A$2497,0)+5),"8. § eleje") -> 8. § eleje
A40: F-TV-0292 | B40: Szervezet | C40: Biztonságért felelős személy adatainak bejelentése | D40: Tv. 1. § (1) a)–c), f); a Tv. 8. § (4), (6) és az 51. alcím figyelembevételével. | E40: A hatály alá kerülést követő 30 napon belül; átmeneti eltérések: Tv. 83–89. §. | F40: =HYPERLINK("#'Forrásszöveg'!A"&(MATCH("TV-S0292",Forrásszöveg!$A$6:$A$2497,0)+5),"Tv. 8. § (4) b)") -> Tv. 8. § (4) b) | G40: Az alapvető és fontos szervezetek általános kötelezettségei | H40: =HYPERLINK("#'Forrásszöveg'!A"&(MATCH("TV-S0285",Forrásszöveg!$A$6:$A$2497,0)+5),"8. § eleje") -> 8. § eleje
A41: F-TV-0293 | B41: Szervezet | C41: Használt elektronikus információs rendszerek felmérése | D41: Tv. 1. § (1) a)–c), f); a Tv. 8. § (4), (6) és az 51. alcím figyelembevételével. | E41: A hatály alá kerülést követő 90 napon belül; átmeneti eltérések: Tv. 83–89. §. | F41: =HYPERLINK("#'Forrásszöveg'!A"&(MATCH("TV-S0293",Forrásszöveg!$A$6:$A$2497,0)+5),"Tv. 8. § (4) c)") -> Tv. 8. § (4) c) | G41: Az alapvető és fontos szervezetek általános kötelezettségei | H41: =HYPERLINK("#'Forrásszöveg'!A"&(MATCH("TV-S0285",Forrásszöveg!$A$6:$A$2497,0)+5),"8. § eleje") -> 8. § eleje
A42: F-TV-0294 | B42: Szervezet | C42: Adatosztályozás elvégzése, ha releváns | D42: Tv. 1. § (1) a)–c), f); a Tv. 8. § (4), (6) és az 51. alcím figyelembevételével. | E42: A hatály alá kerülést követő 120 napon belül; átmeneti eltérések: Tv. 83–89. §. | F42: =HYPERLINK("#'Forrásszöveg'!A"&(MATCH("TV-S0294",Forrásszöveg!$A$6:$A$2497,0)+5),"Tv. 8. § (4) d)") -> Tv. 8. § (4) d) | G42: Az alapvető és fontos szervezetek általános kötelezettségei | H42: =HYPERLINK("#'Forrásszöveg'!A"&(MATCH("TV-S0285",Forrásszöveg!$A$6:$A$2497,0)+5),"8. § eleje") -> 8. § eleje
...

Sheet Jogok
A2: Jogok, lehetőségek és hatáskörök | H2: =HYPERLINK("#'Áttekintő'!A1","Áttekintő") -> Áttekintő
A3: Első tételes kivonat, nem teljes körű. Szűrés: érintett vagy téma; a jogalapra kattintva a pontos szöveg nyílik meg.
A5: Azonosító | B5: Érintett | C5: Jog / hatáskör röviden | D5: Feltétel / kivétel | E5: Időzítés | F5: Jogalap | G5: Téma | H5: Teljes §
A6: J-TV-0274 | B6: Szervezet | C6: Tanúsított IKT-termék vagy szolgáltatás alkalmazása megfelelés igazolására | D6: Ha rendelkezésre áll; nem azonos a 6. § (9) kötelező alkalmazási esetével. | E6: A tétel jogalapjában nincs külön időpont kiemelve. | F6: =HYPERLINK("#'Forrásszöveg'!A"&(MATCH("TV-S0274",Forrásszöveg!$A$6:$A$2497,0)+5),"Tv. 6. § (8)") -> Tv. 6. § (8) | G6: Az alapvető és fontos szervezetek általános kötelezettségei | H6: =HYPERLINK("#'Forrásszöveg'!A"&(MATCH("TV-S0240",Forrásszöveg!$A$6:$A$2497,0)+5),"6. § eleje") -> 6. § eleje
A7: J-TV-0306 | B7: Szervezet | C7: Kiberbiztonsági információmegosztási megállapodás kötése | D7: Honvédelmi célú EIR-re vonatkozó információ kivételével; miniszteri részletszabály szerint. | E7: A tétel jogalapjában nincs külön időpont kiemelve. | F7: =HYPERLINK("#'Forrásszöveg'!A"&(MATCH("TV-S0306",Forrásszöveg!$A$6:$A$2497,0)+5),"Tv. 8. § (7)") -> Tv. 8. § (7) | G7: Az alapvető és fontos szervezetek általános kötelezettségei | H7: =HYPERLINK("#'Forrásszöveg'!A"&(MATCH("TV-S0285",Forrásszöveg!$A$6:$A$2497,0)+5),"8. § eleje") -> 8. § eleje
A8: J-TV-0311 | B8: Szervezet | C8: Nem privát felhő vagy külföldi adatkezelés igénybevétele | D8: A 9. § (4) szerinti kör, adatosztályozás eredményére figyelemmel; más jogszabály tilalma vagy korlátozása mellett. | E8: A tétel jogalapjában nincs külön időpont kiemelve. | F8: =HYPERLINK("#'Forrásszöveg'!A"&(MATCH("TV-S0311",Forrásszöveg!$A$6:$A$2497,0)+5),"Tv. 9. § (4)") -> Tv. 9. § (4) | G8: Adatosztályozás | H8: =HYPERLINK("#'Forrásszöveg'!A"&(MATCH("TV-S0308",Forrásszöveg!$A$6:$A$2497,0)+5),"9. § eleje") -> 9. § eleje
A9: J-TV-0338 | B9: Szervezet vezetője | C9: Titoktartási kötelezettség alóli felmentés adása | D9: A biztonságért felelős személy tekintetében. | E9: A tétel jogalapjában nincs külön időpont kiemelve. | F9: =HYPERLINK("#'Forrásszöveg'!A"&(MATCH("TV-S0338",Forrásszöveg!$A$6:$A$2497,0)+5),"Tv. 11. § (7)") -> Tv. 11. § (7) | G9: Az elektronikus információs rendszer biztonságáért felelős személy | H9: =HYPERLINK("#'Forrásszöveg'!A"&(MATCH("TV-S0322",Forrásszöveg!$A$6:$A$2497,0)+5),"11. § eleje") -> 11. § eleje
A10: J-TV-0340 | B10: Elektronikus információs rendszer biztonságáért felelős személy | C10: Tájékoztatás kérése és szükséges adatok, dokumentumok megismerése | D10: A biztonsági követelmények teljesítésében közreműködőktől, a 11. § (9) szerinti körben. | E10: A tétel jogalapjában nincs külön időpont kiemelve. | F10: =HYPERLINK("#'Forrásszöveg'!A"&(MATCH("TV-S0340",Forrásszöveg!$A$6:$A$2497,0)+5),"Tv. 11. § (9)") -> Tv. 11. § (9) | G10: Az elektronikus információs rendszer biztonságáért felelős személy | H10: =HYPERLINK("#'Forrásszöveg'!A"&(MATCH("TV-S0322",Forrásszöveg!$A$6:$A$2497,0)+5),"11. § eleje") -> 11. § eleje
A11: J-TV-0341 | B11: Szervezet | C11: Helyettes kijelölése vagy megbízása | D11: Indokolt esetben, tartós távollét vagy akadályoztatás kezelésére. | E11: A tétel jogalapjában nincs külön időpont kiemelve. | F11: =HYPERLINK("#'Forrásszöveg'!A"&(MATCH("TV-S0341",Forrásszöveg!$A$6:$A$2497,0)+5),"Tv. 11. § (10)") -> Tv. 11. § (10) | G11: Az elektronikus információs rendszer biztonságáért felelős személy | H11: =HYPERLINK("#'Forrásszöveg'!A"&(MATCH("TV-S0322",Forrásszöveg!$A$6:$A$2497,0)+5),"11. § eleje") -> 11. § eleje
A12: J-TV-0342 | B12: Szervezet | C12: Információbiztonsági szervezeti egység létrehozása | D12: Ha a rendszerek száma, mérete vagy biztonsági igénye indokolja. | E12: A tétel jogalapjában nincs külön időpont kiemelve. | F12: =HYPERLINK("#'Forrásszöveg'!A"&(MATCH("TV-S0342",Forrásszöveg!$A$6:$A$2497,0)+5),"Tv. 11. § (11)") -> Tv. 11. § (11) | G12: Az elektronikus információs rendszer biztonságáért felelős személy | H12: =HYPERLINK("#'Forrásszöveg'!A"&(MATCH("TV-S0322",Forrásszöveg!$A$6:$A$2497,0)+5),"11. § eleje") -> 11. § eleje
A13: J-TV-0347 | B13: Nemzeti kiberbiztonsági hatóság | C13: Büntetlen előélet vizsgálata és bűnügyi adat igénylése | D13: A felelős személy 11. § (3) a) szerinti követelménye ellenőrzésére. | E13: A tétel jogalapjában nincs külön időpont kiemelve. | F13: =HYPERLINK("#'Forrásszöveg'!A"&(MATCH("TV-S0347",Forrásszöveg!$A$6:$A$2497,0)+5),"Tv. 11. § (16)") -> Tv. 11. § (16) | G13: Az elektronikus információs rendszer biztonságáért felelős személy | H13: =HYPERLINK("#'Forrásszöveg'!A"&(MATCH("TV-S0322",Forrásszöveg!$A$6:$A$2497,0)+5),"11. § eleje") -> 11. § eleje
A14: J-TV-0367 | B14: Nemzeti kiberbiztonsági hatóság | C14: Sérülékenységvizsgálat elrendelése | D14: Tv. 13. § szerinti fejlesztési eljárás során. | E14: A tétel jogalapjában nincs külön időpont kiemelve. | F14: =HYPERLINK("#'Forrásszöveg'!A"&(MATCH("TV-S0367",Forrásszöveg!$A$6:$A$2497,0)+5),"Tv. 13. § (7)") -> Tv. 13. § (7) | G14: Az elektronikus információs rendszer fejlesztése, továbbfejlesztése | H14: =HYPERLINK("#'Forrásszöveg'!A"&(MATCH("TV-S0357",Forrásszöveg!$A$6:$A$2497,0)+5),"13. § eleje") -> 13. § eleje
A15: J-TV-0381 | B15: Kiberbiztonsági hatóság | C15: Sérülékenységvizsgálat elrendelése | D15: Tv. 14. § szerinti esetben, indokoltan. | E15: A tétel jogalapjában nincs külön időpont kiemelve. | F15: =HYPERLINK("#'Forrásszöveg'!A"&(MATCH("TV-S0381",Forrásszöveg!$A$6:$A$2497,0)+5),"Tv. 14. § (4)") -> Tv. 14. § (4) | G15: Az elektronikus információs rendszer fejlesztése, továbbfejlesztése | H15: =HYPERLINK("#'Forrásszöveg'!A"&(MATCH("TV-S0373",Forrásszöveg!$A$6:$A$2497,0)+5),"14. § eleje") -> 14. § eleje
A16: J-TV-0403 | B16: Központi rendszer felett rendelkezési jogot gyakorló szervezet | C16: Felhasználói követelmények végrehajtásának ellenőrzése | D16: Tv. 18. § (1) c) szerinti követelmények. | E16: A tétel jogalapjában nincs külön időpont kiemelve. | F16: =HYPERLINK("#'Forrásszöveg'!A"&(MATCH("TV-S0403",Forrásszöveg!$A$6:$A$2497,0)+5),"Tv. 18. § (1) d)") -> Tv. 18. § (1) d) | G16: A központi rendszerekre vonatkozó speciális rendelkezések | H16: =HYPERLINK("#'Forrásszöveg'!A"&(MATCH("TV-S0399",Forrásszöveg!$A$6:$A$2497,0)+5),"18. § eleje") -> 18. § eleje
A17: J-TV-0418 | B17: Nemzeti kiberbiztonsági hatóság | C17: Központi rendszer követelményeinek ellenőrzése | D17: Mind a szolgáltatónál, mind a felhasználónál. | E17: A tétel jogalapjában nincs külön időpont kiemelve. | F17: =HYPERLINK("#'Forrásszöveg'!A"&(MATCH("TV-S0418",Forrásszöveg!$A$6:$A$2497,0)+5),"Tv. 18. § (5)") -> Tv. 18. § (5) | G17: A központi rendszerekre vonatkozó speciális rendelkezések | H17: =HYPERLINK("#'Forrásszöveg'!A"&(MATCH("TV-S0399",Forrásszöveg!$A$6:$A$2497,0)+5),"18. § eleje") -> 18. § eleje
